<mujoco model="piper_right">
    <compiler angle="radian" meshdir="../meshes/" autolimits="true"/>
    <option integrator="RK4" timestep="0.001" gravity="0 0 -9.81" />


    <asset>
        <texture name="grid" type="2d" builtin="checker" rgb1=".1 .2 .3"
        rgb2=".2 .3 .4" width="300" height="300" mark="edge" markrgb=".2 .3 .4"/>
        <material name="grid" texture="grid" texrepeat="2 2" texuniform="true"
        reflectance=".2"/>
        <mesh name="arm_base_link" file="arm_base_link.STL"/>
        <mesh name="link1" file="link1.STL"/>
        <mesh name="link2" file="link2.STL"/>
        <mesh name="link3" file="link3.STL"/>
        <mesh name="link4" file="link4.STL"/>
        <mesh name="link5" file="link5.STL"/>
        <mesh name="link6" file="link6.STL"/>
        <mesh name="p1_Link" file="p1_Link.STL" />
        <mesh name="hand_link" file="hand_link.STL" />
    </asset>
    <default>
        <joint damping="0.1"/>
    </default>
    <worldbody>
        <light pos="0 0 1" mode="trackcom" diffuse="1 1 1" />
        <geom name="ground" type="plane" pos="0 0 -.5" size="2 2 .1" material="grid" solimp=".99 .99 .01" solref=".001 1"/>

        <body name="arm_base">
            <geom type="mesh" contype="0" conaffinity="0" group="1" rgba="1 1 1 1" mesh="arm_base_link" />
            <geom type="mesh" rgba="0.792157 0.819608 0.933333 1" mesh="arm_base_link" />
        </body>
        
        <body name="link1" pos="0 0 0.271" quat="0.707105 0 0 -0.707108">
            <inertial pos="0.00131676 0.000310289 -0.00922875" quat="0.557105 0.432155 0.377373 0.600388" mass="0.097868" diaginertia="9.25942e-05 8.3083e-05 7.69469e-05"/>
            <joint name="joint1" pos="0 0 0" axis="0 0 1" range="-2.618 2.618" actuatorfrcrange="-100 100"/>
            <geom type="mesh" rgba="0.792157 0.819608 0.933333 1" mesh="link1"/>
            <body name="link2" quat="0.524588 0.474136 -0.524592 -0.474136">
                <inertial pos="0.147616 -0.017426 0.00175953" quat="0.0107531 0.706346 -0.0276284 0.707246" mass="0.289571" diaginertia="0.00177449 0.0017305 0.000145443"/>
                <joint name="joint2" pos="0 0 0" axis="0 0 1" range="0 3.14" actuatorfrcrange="-100 100"/>
                <geom type="mesh" rgba="0.792157 0.819608 0.933333 1" mesh="link2"/>
                <body name="link3" pos="0.28503 0 0" quat="0.770418 0 0 0.637539">
                    <inertial pos="0.0156727 0.104467 0.000508487" quat="0.506574 0.477898 -0.524055 0.490268" mass="0.290583" diaginertia="0.000241862 0.000222142 0.000100381"/>
                    <joint name="joint3" pos="0 0 0" axis="0 0 1" range="-2.967 0" actuatorfrcrange="-100 100"/>
                    <geom type="mesh" rgba="0.792157 0.819608 0.933333 1" mesh="link3"/>
                    <body name="link4" pos="0.021984 0.25075 0" quat="0.707105 -0.707108 0 0">
                        <inertial pos="0.000276465 -0.00102804 -0.00472831" quat="0.492305 0.505285 0.503294 0.499017" mass="0.127087" diaginertia="4.87057e-05 4.10595e-05 3.82001e-05"/>
                        <joint name="joint4" pos="0 0 0" axis="0 0 -1" range="-1.832 1.832" actuatorfrcrange="-100 100"/>
                        <geom type="mesh" rgba="0.792157 0.819608 0.933333 1" mesh="link4"/>
                        <body name="link5" quat="0.706432 0.706435 -0.0308433 0.0308435">
                            <inertial pos="8.82261e-05 0.0566829 -0.00196119" quat="0.507447 0.490986 0.506887 0.494466" mass="0.144711" diaginertia="5.63237e-05 4.88652e-05 4.39642e-05"/>
                            <joint name="joint5" pos="0 0 0" axis="0 0 1" range="-1.22 1.22" actuatorfrcrange="-100 100"/>
                            <geom type="mesh" rgba="0.792157 0.819608 0.933333 1" mesh="link5"/>
                            <body name="link6" pos="0 0.091 0.0014165" quat="0.499998 -0.5 -0.5 -0.500002">
                                <inertial pos="9.41121e-09 0.00034121 0.0342123" quat="0.00199308 0.707103 0.00226857 0.707104" mass="0.150196" diaginertia="0.000118283 9.9975e-05 4.3175e-05"/>
                                <joint name="joint6" pos="0 0 0" axis="0 0 -1" range="-3.14 3.14" actuatorfrcrange="-100 100"/>
                                
                                <!-- <geom type="mesh" mesh="p1_Link" /> -->
                                <geom pos="0.0375 0.0375 0.0" axisangle="1 -1 -1 2.1" type="mesh" contype="0" conaffinity="0" group="1" mesh="p1_Link" />


                            </body>
                        </body>
                    </body>
                </body>
            </body>
        </body>
    </worldbody>


    <contact>
        <exclude body1="arm_base" body2="link1"/>
    </contact>

    <!-- Define the actuators for all the joints -->
    <actuator> 
        <motor name="joint1" joint="joint1" ctrllimited="true" ctrlrange="-100 100" gear="1" />
        <motor name="joint2" joint="joint2" ctrllimited="true" ctrlrange="-100 100" gear="1" />
        <motor name="joint3" joint="joint3" ctrllimited="true" ctrlrange="-100 100" gear="1" />
        <motor name="joint4" joint="joint4" ctrllimited="true" ctrlrange="-100 100" gear="1" />
        <motor name="joint5" joint="joint5" ctrllimited="true" ctrlrange="-100 100" gear="1" />
        <motor name="joint6" joint="joint6" ctrllimited="true" ctrlrange="-100 100" gear="1" />
    </actuator>
</mujoco>
